<?xml version="1.0"?>
<robot name="adeept_awr">

<!-- Chassis -->
  <link name="chassis">
    <origin xyz = "0.0 0.0 0.055"/>
    <visual>
      <geometry>
        <box size = "0.13 0.12 0.08"/>
      </geometry>
    </visual>
    <collision>
      <geometry>
        <box size = "0.13 0.12 0.08"/>
      </geometry>
    </collision>
    <!--inertial>
      <origin xyz="0.0 0.0125 0.0"/>
      <mass value="0.500"/>
      <inertia ixx="0.00009565" ixy="0.0" ixz="0" iyy="0.0003999" iyz="0.0" izz="0.0004892"/>
    </inertial-->
  </link>

  <!-- Camera -->
  <joint name="camera_joint" type="fixed">
    <origin xyz="0.07 0.0 0.03" rpy="0 0 0"/>
    <parent link="chassis"/>
    <child link="camera_link"/>
  </joint>
  <link name="camera_link">
    <collision>
      <origin xyz="0.07 0.0 0.03" rpy="0 0 0"/>
      <geometry>
    	<box size="1e-6 1e-6 1e-6"/>
      </geometry>
    </collision>

    <visual>
      <origin xyz="0.07 0.0 0.03" rpy="0 0 0"/>
      <geometry>
    	<box size="1e-6 1e-6 1e-6"/>
      </geometry>
    </visual>

    <inertial>
      <mass value="1e-6" />
      <origin xyz="0 0 0" rpy="0 0 0"/>
      <inertia ixx="1e-6" ixy="0" ixz="0" iyy="1e-6" iyz="0" izz="1e-6" />
    </inertial>
  </link>

  <!-- Battery -->
  <link name="battery">
    <origin xyz = "0.0 0.0 0.0"/>
    <visual>
      <geometry>
        <box size = "0.145 0.065 0.015"/>
      </geometry>
    </visual>
    <collision>
      <geometry>
        <box size = "0.145 0.065 0.015"/>
      </geometry>
    </collision>
    <inertial>
      <origin xyz = "0.0 0.0 0.0"/>
      <mass value="0.005"/>
      <inertia ixx="0.00009435" ixy="0.0" ixz="0" iyy="0.00001117" iyz="0.0" izz="0.0000148"/>
    </inertial>
  </link>

  <!-- Wheels -->
  <link name="front_left_wheel">
    <visual>
      <origin xyz="0.0 0.0125 0.0" rpy="1.5708 0 0"/>
      <geometry>
        <cylinder radius="0.0325" length="0.025"/>
      </geometry>
    </visual>
    <collision>
      <origin xyz="0.0 0.0125 0.0" rpy="1.5708 0 0"/>
      <geometry>
        <cylinder radius="0.0325" length="0.025"/>
      </geometry>
    </collision>
    <inertial>
      <origin xyz="0.0 0.0125 0.0"/>
      <mass value="0.03"/>
      <inertia ixx="0.00001044" ixy="0.0" ixz="0" iyy="0.00001767" iyz="0.0" izz="0.00001044"/>
    </inertial>
  </link>
  <link name="front_right_wheel">
    <visual>
      <origin xyz="0.0 -0.0125 0.0" rpy="1.5708 0 0"/>
      <geometry>
        <cylinder radius="0.0325" length="0.025"/>
      </geometry>
    </visual>
    <collision>
      <origin xyz="0.0 -0.0125 0.0" rpy="1.5708 0 0"/>
      <geometry>
        <cylinder radius="0.0325" length="0.025"/>
      </geometry>
    </collision>
    <inertial>
      <origin xyz="0.0 -0.0125 0.0"/>
      <mass value="0.03"/>
      <inertia ixx="0.00001044" ixy="0.0" ixz="0" iyy="0.00001767" iyz="0.0" izz="0.00001044"/>
    </inertial>
  </link>
  <link name="rear_left_wheel">
    <visual>
      <origin xyz="0.0 0.0125 0.0" rpy="1.5708 0 0"/>
      <geometry>
        <cylinder radius="0.0325" length="0.025"/>
      </geometry>
    </visual>
    <collision>
      <origin xyz="0.0 0.0125 0.0" rpy="1.5708 0 0"/>
      <geometry>
        <cylinder radius="0.0325" length="0.025"/>
      </geometry>
    </collision>
    <inertial>
      <origin xyz="0.0 0.0125 0.0"/>
      <mass value="0.03"/>
      <inertia ixx="0.00001044" ixy="0.0" ixz="0" iyy="0.00001767" iyz="0.0" izz="0.00001044"/>
    </inertial>
  </link>
  <link name="rear_right_wheel">
    <visual>
      <origin xyz="0.0 -0.0125 0.0" rpy="1.5708 0 0"/>
      <geometry>
        <cylinder radius="0.0325" length="0.025"/>
      </geometry>
    </visual>
    <collision>
      <origin xyz="0.0 -0.0125 0.0" rpy="1.5708 0 0"/>
      <geometry>
        <cylinder radius="0.0325" length="0.025"/>
      </geometry>
    </collision>
    <inertial>
      <origin xyz="0.0 -0.0125 0.0"/>
      <mass value="0.03"/>
      <inertia ixx="0.00001044" ixy="0.0" ixz="0" iyy="0.00001767" iyz="0.0" izz="0.00001044"/>
    </inertial>
  </link>

  <!-- Joints -->
  <joint name = "battery_mount" type="fixed">
    <parent link = "chassis"/>
    <child link = "battery"/>
    <origin xyz = "0.015 0.0 0.0475"/>
  </joint>
  <joint name = "rear_right_axle" type="continuous">
    <parent link = "chassis"/>
    <child link = "rear_right_wheel"/>
    <origin xyz = "-0.05 -0.06 -0.02"/>
    <axis xyz = "0 1 0" />
    <limit effort = "0.0784532" velocity="1.55"/>
    <dynamics friction="0.04"/>
  </joint>
  <joint name = "rear_left_axle" type="continuous">
    <parent link = "chassis"/>
    <child link = "rear_left_wheel"/>
    <origin xyz = "-0.05 0.06 -0.02"/>
    <axis xyz = "0 1 0" />
    <limit effort = "0.0784532" velocity="1.55"/>
    <dynamics friction="0.04"/>
  </joint>
  <joint name = "front_left_axle" type="continuous">
    <parent link = "chassis"/>
    <child link = "front_left_wheel"/>
    <origin xyz = "0.03 0.06 -0.02"/>
    <axis xyz = "0 1 0" />
    <limit effort = "0.0784532" velocity="1.55"/>
    <dynamics friction="0.04"/>
  </joint>
  <joint name = "front_right_axle" type="continuous">
    <parent link = "chassis"/>
    <child link = "front_right_wheel"/>
    <origin xyz = "0.03 -0.06 -0.02"/>
    <axis xyz = "0 1 0" />
    <limit effort = "0.0784532" velocity="1.55"/>
    <dynamics friction="0.04"/>
  </joint>

  <!-- Gazebo -->
  <gazebo reference="front_right_wheel">
    <mu1>0.8693</mu1>
    <mu2>0.8693</mu2>
    <material>Gazebo/Black</material>
  </gazebo>
  <gazebo reference="front_left_wheel">
    <mu1>0.8693</mu1>
    <mu2>0.8693</mu2>
    <material>Gazebo/Black</material>
  </gazebo>
  <gazebo reference="rear_right_wheel">
    <mu1>0.8693</mu1>
    <mu2>0.8693</mu2>
    <material>Gazebo/Black</material>
  </gazebo>
  <gazebo reference="rear_left_wheel">
    <mu1>0.8693</mu1>
    <mu2>0.8693</mu2>
    <material>Gazebo/Black</material>
  </gazebo>
  <gazebo>
    <plugin name="skid_steer_drive_controller" filename="libgazebo_ros_skid_steer_drive.so">
      <updateRate>30.0</updateRate>
      <leftFrontJoint>front_left_axle</leftFrontJoint>
      <rightFrontJoint>front_right_axle</rightFrontJoint>
      <leftRearJoint>rear_left_axle</leftRearJoint>
      <rightRearJoint>rear_right_axle</rightRearJoint>
      <wheelSeparation>0.150</wheelSeparation>
      <wheelDiameter>0.065</wheelDiameter>
      <robotBaseFrame>chassis</robotBaseFrame>
      <torque>0.0784532</torque>
      <commandTopic>cmd_vel</commandTopic>
      <broadcastTF>false</broadcastTF>
    </plugin>
    <plugin name="joint_state_publisher" filename="libgazebo_ros_joint_state_publisher.so">
      <jointName>front_left_axle,front_right_axle,rear_left_axle,rear_right_axle</jointName>
      <updateRate>30.0</updateRate>
      <alwaysOn>true</alwaysOn>
    </plugin>
  </gazebo>
  <!-- camera -->
  <gazebo reference="camera_link">
    <sensor type="camera" name="pi_camera">
      <update_rate>15.0</update_rate>
      <camera name="head">
        <horizontal_fov>2.35</horizontal_fov>
        <image>
          <width>1280</width>
          <height>720</height>
          <format>R8G8B8</format>
        </image>
        <clip>
          <near>0.02</near>
          <far>300</far>
        </clip>
        <noise>
          <type>gaussian</type>
          <!-- Noise is sampled independently per pixel on each frame.
               That pixel's noise value is added to each of its color
               channels, which at that point lie in the range [0,1]. -->
          <mean>0.0</mean>
          <stddev>0.007</stddev>
        </noise>
      </camera>
      <plugin name="camera_controller" filename="libgazebo_ros_camera.so">
        <alwaysOn>true</alwaysOn>
        <updateRate>0.0</updateRate>
        <cameraName>pi_camera</cameraName>
        <imageTopicName>image_raw</imageTopicName>
        <cameraInfoTopicName>camera_info</cameraInfoTopicName>
        <frameName>camera_link</frameName>
        <hackBaseline>0.07</hackBaseline>
        <distortionK1>0.0</distortionK1>
        <distortionK2>0.0</distortionK2>
        <distortionK3>0.0</distortionK3>
        <distortionT1>0.0</distortionT1>
        <distortionT2>0.0</distortionT2>
      </plugin>
    </sensor>
  </gazebo>
</robot>